---------------------------------------------------------------------------
ValueError                                Traceback (most recent call last)
Cell In[81], line 3
      1 for n_clusters in range(2, 7):
      2     labels = cluster_kmeans(features, n_clusters)
----> 3     plot_clusters(features, labels,n_clusters)

Cell In[79], line 3, in plot_clusters(features, labels, n_clusters)
      1 def plot_clusters(features, labels,n_clusters):
      2         plt.figure(figsize=(8, 6))
----> 3         unique_labels = np.unique(labels)
      4         colors = plt.cm.jet(np.linspace(0, 1, len(unique_labels))) 
      6         for label, color in zip(unique_labels, colors):

File ~\AppData\Local\anaconda3\Lib\site-packages\numpy\lib\arraysetops.py:272, in unique(ar, return_index, return_inverse, return_counts, axis, equal_nan)
    138 @array_function_dispatch(_unique_dispatcher)
    139 def unique(ar, return_index=False, return_inverse=False,
    140            return_counts=False, axis=None, *, equal_nan=True):
    141     """
    142     Find the unique elements of an array.
    143 
   (...)
    270 
    271     """
--> 272     ar = np.asanyarray(ar)
    273     if axis is None:
    274         ret = _unique1d(ar, return_index, return_inverse, return_counts, 
    275                         equal_nan=equal_nan)

ValueError: setting an array element with a sequence. The requested array has an inhomogeneous shape after 1 dimensions. The detected shape was (2,) + inhomogeneous part.
<Figure size 800x600 with 0 Axes>
